INFO 2025-07-01 21:31:14,856 autoreload 5140 28648 Watching for file changes with StatReloader
INFO 2025-07-01 21:32:05,586 autoreload 5140 28648 C:\am\allifapp\allifapperp\allifmaalcommonapp\models.py changed, reloading.
INFO 2025-07-01 21:32:06,533 autoreload 22612 14628 Watching for file changes with StatReloader
INFO 2025-07-01 21:32:13,490 autoreload 22612 14628 C:\am\allifapp\allifapperp\allifmaalcommonapp\models.py changed, reloading.
INFO 2025-07-01 21:32:14,268 autoreload 33920 1656 Watching for file changes with StatReloader
INFO 2025-07-01 21:32:30,632 autoreload 33920 1656 C:\am\allifapp\allifapperp\allifmaalcommonapp\views.py changed, reloading.
INFO 2025-07-01 21:32:31,787 autoreload 20048 28020 Watching for file changes with StatReloader
INFO 2025-07-01 21:33:12,018 autoreload 20048 28020 C:\am\allifapp\allifapperp\allifmaalcommonapp\views.py changed, reloading.
INFO 2025-07-01 21:33:12,951 autoreload 16500 31188 Watching for file changes with StatReloader
INFO 2025-07-01 21:34:03,539 autoreload 16500 31188 C:\am\allifapp\allifapperp\allifmaalcommonapp\views.py changed, reloading.
INFO 2025-07-01 21:34:04,302 autoreload 22176 36376 Watching for file changes with StatReloader
INFO 2025-07-01 21:35:33,102 autoreload 22176 36376 C:\am\allifapp\allifapperp\allifmaalcommonapp\views.py changed, reloading.
INFO 2025-07-01 21:35:34,095 autoreload 26724 10452 Watching for file changes with StatReloader
ERROR 2025-07-01 21:37:53,216 views 26724 6824 Unexpected error for Tax 'Sales Tax'.
Traceback (most recent call last):
  File "C:\am\allifapp\allifapperp\allifmaalcommonapp\views.py", line 1960, in commonCreateDefaultValues
    _, created = CommonTaxParametersModel.objects.get_or_create(
                 ~~~~~~~~~~~~~~~~~~~~~~~~~~~~~~~~~~~~~~~~~~~~~~^
        taxname=tax_data['taxname'],
        ^^^^^^^^^^^^^^^^^^^^^^^^^^^^
    ...<9 lines>...
        }
        ^
    )
    ^
  File "C:\Users\ahmed\AppData\Local\Programs\Python\Python313\Lib\site-packages\django\db\models\manager.py", line 87, in manager_method
    return getattr(self.get_queryset(), name)(*args, **kwargs)
           ~~~~~~~~~~~~~~~~~~~~~~~~~~~~~~~~~~^^^^^^^^^^^^^^^^^
  File "C:\Users\ahmed\AppData\Local\Programs\Python\Python313\Lib\site-packages\django\db\models\query.py", line 916, in get_or_create
    return self.get(**kwargs), False
           ~~~~~~~~^^^^^^^^^^
  File "C:\Users\ahmed\AppData\Local\Programs\Python\Python313\Lib\site-packages\django\db\models\query.py", line 623, in get
    clone = self._chain() if self.query.combinator else self.filter(*args, **kwargs)
                                                        ~~~~~~~~~~~^^^^^^^^^^^^^^^^^
  File "C:\Users\ahmed\AppData\Local\Programs\Python\Python313\Lib\site-packages\django\db\models\query.py", line 1436, in filter
    return self._filter_or_exclude(False, args, kwargs)
           ~~~~~~~~~~~~~~~~~~~~~~~^^^^^^^^^^^^^^^^^^^^^
  File "C:\Users\ahmed\AppData\Local\Programs\Python\Python313\Lib\site-packages\django\db\models\query.py", line 1454, in _filter_or_exclude
    clone._filter_or_exclude_inplace(negate, args, kwargs)
    ~~~~~~~~~~~~~~~~~~~~~~~~~~~~~~~~^^^^^^^^^^^^^^^^^^^^^^
  File "C:\Users\ahmed\AppData\Local\Programs\Python\Python313\Lib\site-packages\django\db\models\query.py", line 1461, in _filter_or_exclude_inplace
    self._query.add_q(Q(*args, **kwargs))
    ~~~~~~~~~~~~~~~~~^^^^^^^^^^^^^^^^^^^^
  File "C:\Users\ahmed\AppData\Local\Programs\Python\Python313\Lib\site-packages\django\db\models\sql\query.py", line 1546, in add_q
    clause, _ = self._add_q(q_object, self.used_aliases)
                ~~~~~~~~~~~^^^^^^^^^^^^^^^^^^^^^^^^^^^^^
  File "C:\Users\ahmed\AppData\Local\Programs\Python\Python313\Lib\site-packages\django\db\models\sql\query.py", line 1577, in _add_q
    child_clause, needed_inner = self.build_filter(
                                 ~~~~~~~~~~~~~~~~~^
        child,
        ^^^^^^
    ...<6 lines>...
        summarize=summarize,
        ^^^^^^^^^^^^^^^^^^^^
    )
    ^
  File "C:\Users\ahmed\AppData\Local\Programs\Python\Python313\Lib\site-packages\django\db\models\sql\query.py", line 1427, in build_filter
    lookups, parts, reffed_expression = self.solve_lookup_type(arg, summarize)
                                        ~~~~~~~~~~~~~~~~~~~~~~^^^^^^^^^^^^^^^^
  File "C:\Users\ahmed\AppData\Local\Programs\Python\Python313\Lib\site-packages\django\db\models\sql\query.py", line 1237, in solve_lookup_type
    _, field, _, lookup_parts = self.names_to_path(lookup_splitted, self.get_meta())
                                ~~~~~~~~~~~~~~~~~~^^^^^^^^^^^^^^^^^^^^^^^^^^^^^^^^^^
  File "C:\Users\ahmed\AppData\Local\Programs\Python\Python313\Lib\site-packages\django\db\models\sql\query.py", line 1725, in names_to_path
    raise FieldError(
    ...<2 lines>...
    )
django.core.exceptions.FieldError: Cannot resolve keyword 'taxname' into field. Choices are: balance, branch, branch_id, code, comments, company, company_id, date, delete_status, department, department_id, description, division, division_id, ends, id, last_updated, name, number, operation_term, operation_term_id, operation_year, operation_year_id, owner, owner_id, priority, quantity, reference, starts, status, stktxrte, taxrate, taxtype, txinvce, txqr, updated_by, updated_by_id, uuid
ERROR 2025-07-01 21:37:53,222 views 26724 6824 Unexpected error for Supplier Tax 'Sales Tax'.
Traceback (most recent call last):
  File "C:\am\allifapp\allifapperp\allifmaalcommonapp\views.py", line 1986, in commonCreateDefaultValues
    _, created = CommonSupplierTaxParametersModel.objects.get_or_create(
                 ~~~~~~~~~~~~~~~~~~~~~~~~~~~~~~~~~~~~~~~~~~~~~~~~~~~~~~^
        taxname=tax_data['taxname'],
        ^^^^^^^^^^^^^^^^^^^^^^^^^^^^
    ...<9 lines>...
        }
        ^
    )
    ^
  File "C:\Users\ahmed\AppData\Local\Programs\Python\Python313\Lib\site-packages\django\db\models\manager.py", line 87, in manager_method
    return getattr(self.get_queryset(), name)(*args, **kwargs)
           ~~~~~~~~~~~~~~~~~~~~~~~~~~~~~~~~~~^^^^^^^^^^^^^^^^^
  File "C:\Users\ahmed\AppData\Local\Programs\Python\Python313\Lib\site-packages\django\db\models\query.py", line 916, in get_or_create
    return self.get(**kwargs), False
           ~~~~~~~~^^^^^^^^^^
  File "C:\Users\ahmed\AppData\Local\Programs\Python\Python313\Lib\site-packages\django\db\models\query.py", line 623, in get
    clone = self._chain() if self.query.combinator else self.filter(*args, **kwargs)
                                                        ~~~~~~~~~~~^^^^^^^^^^^^^^^^^
  File "C:\Users\ahmed\AppData\Local\Programs\Python\Python313\Lib\site-packages\django\db\models\query.py", line 1436, in filter
    return self._filter_or_exclude(False, args, kwargs)
           ~~~~~~~~~~~~~~~~~~~~~~~^^^^^^^^^^^^^^^^^^^^^
  File "C:\Users\ahmed\AppData\Local\Programs\Python\Python313\Lib\site-packages\django\db\models\query.py", line 1454, in _filter_or_exclude
    clone._filter_or_exclude_inplace(negate, args, kwargs)
    ~~~~~~~~~~~~~~~~~~~~~~~~~~~~~~~~^^^^^^^^^^^^^^^^^^^^^^
  File "C:\Users\ahmed\AppData\Local\Programs\Python\Python313\Lib\site-packages\django\db\models\query.py", line 1461, in _filter_or_exclude_inplace
    self._query.add_q(Q(*args, **kwargs))
    ~~~~~~~~~~~~~~~~~^^^^^^^^^^^^^^^^^^^^
  File "C:\Users\ahmed\AppData\Local\Programs\Python\Python313\Lib\site-packages\django\db\models\sql\query.py", line 1546, in add_q
    clause, _ = self._add_q(q_object, self.used_aliases)
                ~~~~~~~~~~~^^^^^^^^^^^^^^^^^^^^^^^^^^^^^
  File "C:\Users\ahmed\AppData\Local\Programs\Python\Python313\Lib\site-packages\django\db\models\sql\query.py", line 1577, in _add_q
    child_clause, needed_inner = self.build_filter(
                                 ~~~~~~~~~~~~~~~~~^
        child,
        ^^^^^^
    ...<6 lines>...
        summarize=summarize,
        ^^^^^^^^^^^^^^^^^^^^
    )
    ^
  File "C:\Users\ahmed\AppData\Local\Programs\Python\Python313\Lib\site-packages\django\db\models\sql\query.py", line 1427, in build_filter
    lookups, parts, reffed_expression = self.solve_lookup_type(arg, summarize)
                                        ~~~~~~~~~~~~~~~~~~~~~~^^^^^^^^^^^^^^^^
  File "C:\Users\ahmed\AppData\Local\Programs\Python\Python313\Lib\site-packages\django\db\models\sql\query.py", line 1237, in solve_lookup_type
    _, field, _, lookup_parts = self.names_to_path(lookup_splitted, self.get_meta())
                                ~~~~~~~~~~~~~~~~~~^^^^^^^^^^^^^^^^^^^^^^^^^^^^^^^^^^
  File "C:\Users\ahmed\AppData\Local\Programs\Python\Python313\Lib\site-packages\django\db\models\sql\query.py", line 1725, in names_to_path
    raise FieldError(
    ...<2 lines>...
    )
django.core.exceptions.FieldError: Cannot resolve keyword 'taxname' into field. Choices are: balance, branch, branch_id, code, comments, company, company_id, date, delete_status, department, department_id, description, division, division_id, ends, id, last_updated, name, number, operation_term, operation_term_id, operation_year, operation_year_id, owner, owner_id, priority, quantity, reference, sppltxrt, starts, status, supplrstktxrte, taxrate, taxtype, updated_by, updated_by_id, uuid
ERROR 2025-07-01 21:37:53,224 views 26724 6824 Unexpected error for Tax 'VAT'.
Traceback (most recent call last):
  File "C:\am\allifapp\allifapperp\allifmaalcommonapp\views.py", line 1960, in commonCreateDefaultValues
    _, created = CommonTaxParametersModel.objects.get_or_create(
                 ~~~~~~~~~~~~~~~~~~~~~~~~~~~~~~~~~~~~~~~~~~~~~~^
        taxname=tax_data['taxname'],
        ^^^^^^^^^^^^^^^^^^^^^^^^^^^^
    ...<9 lines>...
        }
        ^
    )
    ^
  File "C:\Users\ahmed\AppData\Local\Programs\Python\Python313\Lib\site-packages\django\db\models\manager.py", line 87, in manager_method
    return getattr(self.get_queryset(), name)(*args, **kwargs)
           ~~~~~~~~~~~~~~~~~~~~~~~~~~~~~~~~~~^^^^^^^^^^^^^^^^^
  File "C:\Users\ahmed\AppData\Local\Programs\Python\Python313\Lib\site-packages\django\db\models\query.py", line 916, in get_or_create
    return self.get(**kwargs), False
           ~~~~~~~~^^^^^^^^^^
  File "C:\Users\ahmed\AppData\Local\Programs\Python\Python313\Lib\site-packages\django\db\models\query.py", line 623, in get
    clone = self._chain() if self.query.combinator else self.filter(*args, **kwargs)
                                                        ~~~~~~~~~~~^^^^^^^^^^^^^^^^^
  File "C:\Users\ahmed\AppData\Local\Programs\Python\Python313\Lib\site-packages\django\db\models\query.py", line 1436, in filter
    return self._filter_or_exclude(False, args, kwargs)
           ~~~~~~~~~~~~~~~~~~~~~~~^^^^^^^^^^^^^^^^^^^^^
  File "C:\Users\ahmed\AppData\Local\Programs\Python\Python313\Lib\site-packages\django\db\models\query.py", line 1454, in _filter_or_exclude
    clone._filter_or_exclude_inplace(negate, args, kwargs)
    ~~~~~~~~~~~~~~~~~~~~~~~~~~~~~~~~^^^^^^^^^^^^^^^^^^^^^^
  File "C:\Users\ahmed\AppData\Local\Programs\Python\Python313\Lib\site-packages\django\db\models\query.py", line 1461, in _filter_or_exclude_inplace
    self._query.add_q(Q(*args, **kwargs))
    ~~~~~~~~~~~~~~~~~^^^^^^^^^^^^^^^^^^^^
  File "C:\Users\ahmed\AppData\Local\Programs\Python\Python313\Lib\site-packages\django\db\models\sql\query.py", line 1546, in add_q
    clause, _ = self._add_q(q_object, self.used_aliases)
                ~~~~~~~~~~~^^^^^^^^^^^^^^^^^^^^^^^^^^^^^
  File "C:\Users\ahmed\AppData\Local\Programs\Python\Python313\Lib\site-packages\django\db\models\sql\query.py", line 1577, in _add_q
    child_clause, needed_inner = self.build_filter(
                                 ~~~~~~~~~~~~~~~~~^
        child,
        ^^^^^^
    ...<6 lines>...
        summarize=summarize,
        ^^^^^^^^^^^^^^^^^^^^
    )
    ^
  File "C:\Users\ahmed\AppData\Local\Programs\Python\Python313\Lib\site-packages\django\db\models\sql\query.py", line 1427, in build_filter
    lookups, parts, reffed_expression = self.solve_lookup_type(arg, summarize)
                                        ~~~~~~~~~~~~~~~~~~~~~~^^^^^^^^^^^^^^^^
  File "C:\Users\ahmed\AppData\Local\Programs\Python\Python313\Lib\site-packages\django\db\models\sql\query.py", line 1237, in solve_lookup_type
    _, field, _, lookup_parts = self.names_to_path(lookup_splitted, self.get_meta())
                                ~~~~~~~~~~~~~~~~~~^^^^^^^^^^^^^^^^^^^^^^^^^^^^^^^^^^
  File "C:\Users\ahmed\AppData\Local\Programs\Python\Python313\Lib\site-packages\django\db\models\sql\query.py", line 1725, in names_to_path
    raise FieldError(
    ...<2 lines>...
    )
django.core.exceptions.FieldError: Cannot resolve keyword 'taxname' into field. Choices are: balance, branch, branch_id, code, comments, company, company_id, date, delete_status, department, department_id, description, division, division_id, ends, id, last_updated, name, number, operation_term, operation_term_id, operation_year, operation_year_id, owner, owner_id, priority, quantity, reference, starts, status, stktxrte, taxrate, taxtype, txinvce, txqr, updated_by, updated_by_id, uuid
ERROR 2025-07-01 21:37:53,226 views 26724 6824 Unexpected error for Supplier Tax 'VAT'.
Traceback (most recent call last):
  File "C:\am\allifapp\allifapperp\allifmaalcommonapp\views.py", line 1986, in commonCreateDefaultValues
    _, created = CommonSupplierTaxParametersModel.objects.get_or_create(
                 ~~~~~~~~~~~~~~~~~~~~~~~~~~~~~~~~~~~~~~~~~~~~~~~~~~~~~~^
        taxname=tax_data['taxname'],
        ^^^^^^^^^^^^^^^^^^^^^^^^^^^^
    ...<9 lines>...
        }
        ^
    )
    ^
  File "C:\Users\ahmed\AppData\Local\Programs\Python\Python313\Lib\site-packages\django\db\models\manager.py", line 87, in manager_method
    return getattr(self.get_queryset(), name)(*args, **kwargs)
           ~~~~~~~~~~~~~~~~~~~~~~~~~~~~~~~~~~^^^^^^^^^^^^^^^^^
  File "C:\Users\ahmed\AppData\Local\Programs\Python\Python313\Lib\site-packages\django\db\models\query.py", line 916, in get_or_create
    return self.get(**kwargs), False
           ~~~~~~~~^^^^^^^^^^
  File "C:\Users\ahmed\AppData\Local\Programs\Python\Python313\Lib\site-packages\django\db\models\query.py", line 623, in get
    clone = self._chain() if self.query.combinator else self.filter(*args, **kwargs)
                                                        ~~~~~~~~~~~^^^^^^^^^^^^^^^^^
  File "C:\Users\ahmed\AppData\Local\Programs\Python\Python313\Lib\site-packages\django\db\models\query.py", line 1436, in filter
    return self._filter_or_exclude(False, args, kwargs)
           ~~~~~~~~~~~~~~~~~~~~~~~^^^^^^^^^^^^^^^^^^^^^
  File "C:\Users\ahmed\AppData\Local\Programs\Python\Python313\Lib\site-packages\django\db\models\query.py", line 1454, in _filter_or_exclude
    clone._filter_or_exclude_inplace(negate, args, kwargs)
    ~~~~~~~~~~~~~~~~~~~~~~~~~~~~~~~~^^^^^^^^^^^^^^^^^^^^^^
  File "C:\Users\ahmed\AppData\Local\Programs\Python\Python313\Lib\site-packages\django\db\models\query.py", line 1461, in _filter_or_exclude_inplace
    self._query.add_q(Q(*args, **kwargs))
    ~~~~~~~~~~~~~~~~~^^^^^^^^^^^^^^^^^^^^
  File "C:\Users\ahmed\AppData\Local\Programs\Python\Python313\Lib\site-packages\django\db\models\sql\query.py", line 1546, in add_q
    clause, _ = self._add_q(q_object, self.used_aliases)
                ~~~~~~~~~~~^^^^^^^^^^^^^^^^^^^^^^^^^^^^^
  File "C:\Users\ahmed\AppData\Local\Programs\Python\Python313\Lib\site-packages\django\db\models\sql\query.py", line 1577, in _add_q
    child_clause, needed_inner = self.build_filter(
                                 ~~~~~~~~~~~~~~~~~^
        child,
        ^^^^^^
    ...<6 lines>...
        summarize=summarize,
        ^^^^^^^^^^^^^^^^^^^^
    )
    ^
  File "C:\Users\ahmed\AppData\Local\Programs\Python\Python313\Lib\site-packages\django\db\models\sql\query.py", line 1427, in build_filter
    lookups, parts, reffed_expression = self.solve_lookup_type(arg, summarize)
                                        ~~~~~~~~~~~~~~~~~~~~~~^^^^^^^^^^^^^^^^
  File "C:\Users\ahmed\AppData\Local\Programs\Python\Python313\Lib\site-packages\django\db\models\sql\query.py", line 1237, in solve_lookup_type
    _, field, _, lookup_parts = self.names_to_path(lookup_splitted, self.get_meta())
                                ~~~~~~~~~~~~~~~~~~^^^^^^^^^^^^^^^^^^^^^^^^^^^^^^^^^^
  File "C:\Users\ahmed\AppData\Local\Programs\Python\Python313\Lib\site-packages\django\db\models\sql\query.py", line 1725, in names_to_path
    raise FieldError(
    ...<2 lines>...
    )
django.core.exceptions.FieldError: Cannot resolve keyword 'taxname' into field. Choices are: balance, branch, branch_id, code, comments, company, company_id, date, delete_status, department, department_id, description, division, division_id, ends, id, last_updated, name, number, operation_term, operation_term_id, operation_year, operation_year_id, owner, owner_id, priority, quantity, reference, sppltxrt, starts, status, supplrstktxrte, taxrate, taxtype, updated_by, updated_by_id, uuid
ERROR 2025-07-01 21:37:53,228 views 26724 6824 Unexpected error for Tax 'Withholding Tax'.
Traceback (most recent call last):
  File "C:\am\allifapp\allifapperp\allifmaalcommonapp\views.py", line 1960, in commonCreateDefaultValues
    _, created = CommonTaxParametersModel.objects.get_or_create(
                 ~~~~~~~~~~~~~~~~~~~~~~~~~~~~~~~~~~~~~~~~~~~~~~^
        taxname=tax_data['taxname'],
        ^^^^^^^^^^^^^^^^^^^^^^^^^^^^
    ...<9 lines>...
        }
        ^
    )
    ^
  File "C:\Users\ahmed\AppData\Local\Programs\Python\Python313\Lib\site-packages\django\db\models\manager.py", line 87, in manager_method
    return getattr(self.get_queryset(), name)(*args, **kwargs)
           ~~~~~~~~~~~~~~~~~~~~~~~~~~~~~~~~~~^^^^^^^^^^^^^^^^^
  File "C:\Users\ahmed\AppData\Local\Programs\Python\Python313\Lib\site-packages\django\db\models\query.py", line 916, in get_or_create
    return self.get(**kwargs), False
           ~~~~~~~~^^^^^^^^^^
  File "C:\Users\ahmed\AppData\Local\Programs\Python\Python313\Lib\site-packages\django\db\models\query.py", line 623, in get
    clone = self._chain() if self.query.combinator else self.filter(*args, **kwargs)
                                                        ~~~~~~~~~~~^^^^^^^^^^^^^^^^^
  File "C:\Users\ahmed\AppData\Local\Programs\Python\Python313\Lib\site-packages\django\db\models\query.py", line 1436, in filter
    return self._filter_or_exclude(False, args, kwargs)
           ~~~~~~~~~~~~~~~~~~~~~~~^^^^^^^^^^^^^^^^^^^^^
  File "C:\Users\ahmed\AppData\Local\Programs\Python\Python313\Lib\site-packages\django\db\models\query.py", line 1454, in _filter_or_exclude
    clone._filter_or_exclude_inplace(negate, args, kwargs)
    ~~~~~~~~~~~~~~~~~~~~~~~~~~~~~~~~^^^^^^^^^^^^^^^^^^^^^^
  File "C:\Users\ahmed\AppData\Local\Programs\Python\Python313\Lib\site-packages\django\db\models\query.py", line 1461, in _filter_or_exclude_inplace
    self._query.add_q(Q(*args, **kwargs))
    ~~~~~~~~~~~~~~~~~^^^^^^^^^^^^^^^^^^^^
  File "C:\Users\ahmed\AppData\Local\Programs\Python\Python313\Lib\site-packages\django\db\models\sql\query.py", line 1546, in add_q
    clause, _ = self._add_q(q_object, self.used_aliases)
                ~~~~~~~~~~~^^^^^^^^^^^^^^^^^^^^^^^^^^^^^
  File "C:\Users\ahmed\AppData\Local\Programs\Python\Python313\Lib\site-packages\django\db\models\sql\query.py", line 1577, in _add_q
    child_clause, needed_inner = self.build_filter(
                                 ~~~~~~~~~~~~~~~~~^
        child,
        ^^^^^^
    ...<6 lines>...
        summarize=summarize,
        ^^^^^^^^^^^^^^^^^^^^
    )
    ^
  File "C:\Users\ahmed\AppData\Local\Programs\Python\Python313\Lib\site-packages\django\db\models\sql\query.py", line 1427, in build_filter
    lookups, parts, reffed_expression = self.solve_lookup_type(arg, summarize)
                                        ~~~~~~~~~~~~~~~~~~~~~~^^^^^^^^^^^^^^^^
  File "C:\Users\ahmed\AppData\Local\Programs\Python\Python313\Lib\site-packages\django\db\models\sql\query.py", line 1237, in solve_lookup_type
    _, field, _, lookup_parts = self.names_to_path(lookup_splitted, self.get_meta())
                                ~~~~~~~~~~~~~~~~~~^^^^^^^^^^^^^^^^^^^^^^^^^^^^^^^^^^
  File "C:\Users\ahmed\AppData\Local\Programs\Python\Python313\Lib\site-packages\django\db\models\sql\query.py", line 1725, in names_to_path
    raise FieldError(
    ...<2 lines>...
    )
django.core.exceptions.FieldError: Cannot resolve keyword 'taxname' into field. Choices are: balance, branch, branch_id, code, comments, company, company_id, date, delete_status, department, department_id, description, division, division_id, ends, id, last_updated, name, number, operation_term, operation_term_id, operation_year, operation_year_id, owner, owner_id, priority, quantity, reference, starts, status, stktxrte, taxrate, taxtype, txinvce, txqr, updated_by, updated_by_id, uuid
ERROR 2025-07-01 21:37:53,230 views 26724 6824 Unexpected error for Supplier Tax 'Withholding Tax'.
Traceback (most recent call last):
  File "C:\am\allifapp\allifapperp\allifmaalcommonapp\views.py", line 1986, in commonCreateDefaultValues
    _, created = CommonSupplierTaxParametersModel.objects.get_or_create(
                 ~~~~~~~~~~~~~~~~~~~~~~~~~~~~~~~~~~~~~~~~~~~~~~~~~~~~~~^
        taxname=tax_data['taxname'],
        ^^^^^^^^^^^^^^^^^^^^^^^^^^^^
    ...<9 lines>...
        }
        ^
    )
    ^
  File "C:\Users\ahmed\AppData\Local\Programs\Python\Python313\Lib\site-packages\django\db\models\manager.py", line 87, in manager_method
    return getattr(self.get_queryset(), name)(*args, **kwargs)
           ~~~~~~~~~~~~~~~~~~~~~~~~~~~~~~~~~~^^^^^^^^^^^^^^^^^
  File "C:\Users\ahmed\AppData\Local\Programs\Python\Python313\Lib\site-packages\django\db\models\query.py", line 916, in get_or_create
    return self.get(**kwargs), False
           ~~~~~~~~^^^^^^^^^^
  File "C:\Users\ahmed\AppData\Local\Programs\Python\Python313\Lib\site-packages\django\db\models\query.py", line 623, in get
    clone = self._chain() if self.query.combinator else self.filter(*args, **kwargs)
                                                        ~~~~~~~~~~~^^^^^^^^^^^^^^^^^
  File "C:\Users\ahmed\AppData\Local\Programs\Python\Python313\Lib\site-packages\django\db\models\query.py", line 1436, in filter
    return self._filter_or_exclude(False, args, kwargs)
           ~~~~~~~~~~~~~~~~~~~~~~~^^^^^^^^^^^^^^^^^^^^^
  File "C:\Users\ahmed\AppData\Local\Programs\Python\Python313\Lib\site-packages\django\db\models\query.py", line 1454, in _filter_or_exclude
    clone._filter_or_exclude_inplace(negate, args, kwargs)
    ~~~~~~~~~~~~~~~~~~~~~~~~~~~~~~~~^^^^^^^^^^^^^^^^^^^^^^
  File "C:\Users\ahmed\AppData\Local\Programs\Python\Python313\Lib\site-packages\django\db\models\query.py", line 1461, in _filter_or_exclude_inplace
    self._query.add_q(Q(*args, **kwargs))
    ~~~~~~~~~~~~~~~~~^^^^^^^^^^^^^^^^^^^^
  File "C:\Users\ahmed\AppData\Local\Programs\Python\Python313\Lib\site-packages\django\db\models\sql\query.py", line 1546, in add_q
    clause, _ = self._add_q(q_object, self.used_aliases)
                ~~~~~~~~~~~^^^^^^^^^^^^^^^^^^^^^^^^^^^^^
  File "C:\Users\ahmed\AppData\Local\Programs\Python\Python313\Lib\site-packages\django\db\models\sql\query.py", line 1577, in _add_q
    child_clause, needed_inner = self.build_filter(
                                 ~~~~~~~~~~~~~~~~~^
        child,
        ^^^^^^
    ...<6 lines>...
        summarize=summarize,
        ^^^^^^^^^^^^^^^^^^^^
    )
    ^
  File "C:\Users\ahmed\AppData\Local\Programs\Python\Python313\Lib\site-packages\django\db\models\sql\query.py", line 1427, in build_filter
    lookups, parts, reffed_expression = self.solve_lookup_type(arg, summarize)
                                        ~~~~~~~~~~~~~~~~~~~~~~^^^^^^^^^^^^^^^^
  File "C:\Users\ahmed\AppData\Local\Programs\Python\Python313\Lib\site-packages\django\db\models\sql\query.py", line 1237, in solve_lookup_type
    _, field, _, lookup_parts = self.names_to_path(lookup_splitted, self.get_meta())
                                ~~~~~~~~~~~~~~~~~~^^^^^^^^^^^^^^^^^^^^^^^^^^^^^^^^^^
  File "C:\Users\ahmed\AppData\Local\Programs\Python\Python313\Lib\site-packages\django\db\models\sql\query.py", line 1725, in names_to_path
    raise FieldError(
    ...<2 lines>...
    )
django.core.exceptions.FieldError: Cannot resolve keyword 'taxname' into field. Choices are: balance, branch, branch_id, code, comments, company, company_id, date, delete_status, department, department_id, description, division, division_id, ends, id, last_updated, name, number, operation_term, operation_term_id, operation_year, operation_year_id, owner, owner_id, priority, quantity, reference, sppltxrt, starts, status, supplrstktxrte, taxrate, taxtype, updated_by, updated_by_id, uuid
ERROR 2025-07-01 21:37:53,302 views 26724 6824 Unexpected error for Operation Year 'Operation Year One'.
Traceback (most recent call last):
  File "C:\Users\ahmed\AppData\Local\Programs\Python\Python313\Lib\site-packages\django\db\models\query.py", line 916, in get_or_create
    return self.get(**kwargs), False
           ~~~~~~~~^^^^^^^^^^
  File "C:\Users\ahmed\AppData\Local\Programs\Python\Python313\Lib\site-packages\django\db\models\query.py", line 637, in get
    raise self.model.DoesNotExist(
        "%s matching query does not exist." % self.model._meta.object_name
    )
allifmaalcommonapp.models.CommonOperationYearsModel.DoesNotExist: CommonOperationYearsModel matching query does not exist.

During handling of the above exception, another exception occurred:

Traceback (most recent call last):
  File "C:\am\allifapp\allifapperp\allifmaalcommonapp\views.py", line 2092, in commonCreateDefaultValues
    year_instance, created = CommonOperationYearsModel.objects.get_or_create(
                             ~~~~~~~~~~~~~~~~~~~~~~~~~~~~~~~~~~~~~~~~~~~~~~~^
        year=year_data['year'], # Assuming 'year' is the unique identifier field
        ^^^^^^^^^^^^^^^^^^^^^^^^^^^^^^^^^^^^^^^^^^^^^^^^^^^^^^^^^^^^^^^^^^^^^^^^
    ...<10 lines>...
        }
        ^
    )
    ^
  File "C:\Users\ahmed\AppData\Local\Programs\Python\Python313\Lib\site-packages\django\db\models\manager.py", line 87, in manager_method
    return getattr(self.get_queryset(), name)(*args, **kwargs)
           ~~~~~~~~~~~~~~~~~~~~~~~~~~~~~~~~~~^^^^^^^^^^^^^^^^^
  File "C:\Users\ahmed\AppData\Local\Programs\Python\Python313\Lib\site-packages\django\db\models\query.py", line 918, in get_or_create
    params = self._extract_model_params(defaults, **kwargs)
  File "C:\Users\ahmed\AppData\Local\Programs\Python\Python313\Lib\site-packages\django\db\models\query.py", line 999, in _extract_model_params
    raise exceptions.FieldError(
    ...<5 lines>...
    )
django.core.exceptions.FieldError: Invalid field name(s) for model CommonOperationYearsModel: 'end_date', 'start_date'.
ERROR 2025-07-01 21:37:53,305 views 26724 6824 Unexpected error for Operation Year 'Current Year'.
Traceback (most recent call last):
  File "C:\Users\ahmed\AppData\Local\Programs\Python\Python313\Lib\site-packages\django\db\models\query.py", line 916, in get_or_create
    return self.get(**kwargs), False
           ~~~~~~~~^^^^^^^^^^
  File "C:\Users\ahmed\AppData\Local\Programs\Python\Python313\Lib\site-packages\django\db\models\query.py", line 637, in get
    raise self.model.DoesNotExist(
        "%s matching query does not exist." % self.model._meta.object_name
    )
allifmaalcommonapp.models.CommonOperationYearsModel.DoesNotExist: CommonOperationYearsModel matching query does not exist.

During handling of the above exception, another exception occurred:

Traceback (most recent call last):
  File "C:\am\allifapp\allifapperp\allifmaalcommonapp\views.py", line 2092, in commonCreateDefaultValues
    year_instance, created = CommonOperationYearsModel.objects.get_or_create(
                             ~~~~~~~~~~~~~~~~~~~~~~~~~~~~~~~~~~~~~~~~~~~~~~~^
        year=year_data['year'], # Assuming 'year' is the unique identifier field
        ^^^^^^^^^^^^^^^^^^^^^^^^^^^^^^^^^^^^^^^^^^^^^^^^^^^^^^^^^^^^^^^^^^^^^^^^
    ...<10 lines>...
        }
        ^
    )
    ^
  File "C:\Users\ahmed\AppData\Local\Programs\Python\Python313\Lib\site-packages\django\db\models\manager.py", line 87, in manager_method
    return getattr(self.get_queryset(), name)(*args, **kwargs)
           ~~~~~~~~~~~~~~~~~~~~~~~~~~~~~~~~~~^^^^^^^^^^^^^^^^^
  File "C:\Users\ahmed\AppData\Local\Programs\Python\Python313\Lib\site-packages\django\db\models\query.py", line 918, in get_or_create
    params = self._extract_model_params(defaults, **kwargs)
  File "C:\Users\ahmed\AppData\Local\Programs\Python\Python313\Lib\site-packages\django\db\models\query.py", line 999, in _extract_model_params
    raise exceptions.FieldError(
    ...<5 lines>...
    )
django.core.exceptions.FieldError: Invalid field name(s) for model CommonOperationYearsModel: 'end_date', 'start_date'.
ERROR 2025-07-01 21:37:53,307 views 26724 6824 Skipping term 'Term One' due to missing parent year 'Operation Year One'.
ERROR 2025-07-01 21:37:53,307 views 26724 6824 Skipping term 'Term Two' due to missing parent year 'Operation Year One'.
ERROR 2025-07-01 21:37:53,307 views 26724 6824 Skipping term 'Term Three' due to missing parent year 'Operation Year One'.
ERROR 2025-07-01 21:37:53,307 views 26724 6824 Skipping term 'Term Four' due to missing parent year 'Operation Year One'.
ERROR 2025-07-01 21:37:53,307 views 26724 6824 Skipping term 'Q1' due to missing parent year 'Current Year'.
ERROR 2025-07-01 21:37:53,307 views 26724 6824 Skipping term 'Q2' due to missing parent year 'Current Year'.
ERROR 2025-07-01 21:37:53,307 views 26724 6824 Skipping term 'Q3' due to missing parent year 'Current Year'.
ERROR 2025-07-01 21:37:53,307 views 26724 6824 Skipping term 'Q4' due to missing parent year 'Current Year'.
ERROR 2025-07-01 21:37:53,325 views 26724 6824 Unexpected error for Category 'General Category 1'.
Traceback (most recent call last):
  File "C:\Users\ahmed\AppData\Local\Programs\Python\Python313\Lib\site-packages\django\db\models\query.py", line 916, in get_or_create
    return self.get(**kwargs), False
           ~~~~~~~~^^^^^^^^^^
  File "C:\Users\ahmed\AppData\Local\Programs\Python\Python313\Lib\site-packages\django\db\models\query.py", line 637, in get
    raise self.model.DoesNotExist(
        "%s matching query does not exist." % self.model._meta.object_name
    )
allifmaalcommonapp.models.CommonCategoriesModel.DoesNotExist: CommonCategoriesModel matching query does not exist.

During handling of the above exception, another exception occurred:

Traceback (most recent call last):
  File "C:\am\allifapp\allifapperp\allifmaalcommonapp\views.py", line 2190, in commonCreateDefaultValues
    _, created = CommonCategoriesModel.objects.get_or_create(
                 ~~~~~~~~~~~~~~~~~~~~~~~~~~~~~~~~~~~~~~~~~~~^
        name=cat_data['name'], # Assuming 'name' is the unique identifier field
        ^^^^^^^^^^^^^^^^^^^^^^^^^^^^^^^^^^^^^^^^^^^^^^^^^^^^^^^^^^^^^^^^^^^^^^^
    ...<11 lines>...
        }
        ^
    )
    ^
  File "C:\Users\ahmed\AppData\Local\Programs\Python\Python313\Lib\site-packages\django\db\models\manager.py", line 87, in manager_method
    return getattr(self.get_queryset(), name)(*args, **kwargs)
           ~~~~~~~~~~~~~~~~~~~~~~~~~~~~~~~~~~^^^^^^^^^^^^^^^^^
  File "C:\Users\ahmed\AppData\Local\Programs\Python\Python313\Lib\site-packages\django\db\models\query.py", line 918, in get_or_create
    params = self._extract_model_params(defaults, **kwargs)
  File "C:\Users\ahmed\AppData\Local\Programs\Python\Python313\Lib\site-packages\django\db\models\query.py", line 999, in _extract_model_params
    raise exceptions.FieldError(
    ...<5 lines>...
    )
django.core.exceptions.FieldError: Invalid field name(s) for model CommonCategoriesModel: 'end_date', 'start_date'.
ERROR 2025-07-01 21:37:53,328 views 26724 6824 Unexpected error for Category 'General Category 2'.
Traceback (most recent call last):
  File "C:\Users\ahmed\AppData\Local\Programs\Python\Python313\Lib\site-packages\django\db\models\query.py", line 916, in get_or_create
    return self.get(**kwargs), False
           ~~~~~~~~^^^^^^^^^^
  File "C:\Users\ahmed\AppData\Local\Programs\Python\Python313\Lib\site-packages\django\db\models\query.py", line 637, in get
    raise self.model.DoesNotExist(
        "%s matching query does not exist." % self.model._meta.object_name
    )
allifmaalcommonapp.models.CommonCategoriesModel.DoesNotExist: CommonCategoriesModel matching query does not exist.

During handling of the above exception, another exception occurred:

Traceback (most recent call last):
  File "C:\am\allifapp\allifapperp\allifmaalcommonapp\views.py", line 2190, in commonCreateDefaultValues
    _, created = CommonCategoriesModel.objects.get_or_create(
                 ~~~~~~~~~~~~~~~~~~~~~~~~~~~~~~~~~~~~~~~~~~~^
        name=cat_data['name'], # Assuming 'name' is the unique identifier field
        ^^^^^^^^^^^^^^^^^^^^^^^^^^^^^^^^^^^^^^^^^^^^^^^^^^^^^^^^^^^^^^^^^^^^^^^
    ...<11 lines>...
        }
        ^
    )
    ^
  File "C:\Users\ahmed\AppData\Local\Programs\Python\Python313\Lib\site-packages\django\db\models\manager.py", line 87, in manager_method
    return getattr(self.get_queryset(), name)(*args, **kwargs)
           ~~~~~~~~~~~~~~~~~~~~~~~~~~~~~~~~~~^^^^^^^^^^^^^^^^^
  File "C:\Users\ahmed\AppData\Local\Programs\Python\Python313\Lib\site-packages\django\db\models\query.py", line 918, in get_or_create
    params = self._extract_model_params(defaults, **kwargs)
  File "C:\Users\ahmed\AppData\Local\Programs\Python\Python313\Lib\site-packages\django\db\models\query.py", line 999, in _extract_model_params
    raise exceptions.FieldError(
    ...<5 lines>...
    )
django.core.exceptions.FieldError: Invalid field name(s) for model CommonCategoriesModel: 'end_date', 'start_date'.
ERROR 2025-07-01 21:37:53,330 views 26724 6824 Unexpected error for Category 'Product Category - Electronics'.
Traceback (most recent call last):
  File "C:\Users\ahmed\AppData\Local\Programs\Python\Python313\Lib\site-packages\django\db\models\query.py", line 916, in get_or_create
    return self.get(**kwargs), False
           ~~~~~~~~^^^^^^^^^^
  File "C:\Users\ahmed\AppData\Local\Programs\Python\Python313\Lib\site-packages\django\db\models\query.py", line 637, in get
    raise self.model.DoesNotExist(
        "%s matching query does not exist." % self.model._meta.object_name
    )
allifmaalcommonapp.models.CommonCategoriesModel.DoesNotExist: CommonCategoriesModel matching query does not exist.

During handling of the above exception, another exception occurred:

Traceback (most recent call last):
  File "C:\am\allifapp\allifapperp\allifmaalcommonapp\views.py", line 2190, in commonCreateDefaultValues
    _, created = CommonCategoriesModel.objects.get_or_create(
                 ~~~~~~~~~~~~~~~~~~~~~~~~~~~~~~~~~~~~~~~~~~~^
        name=cat_data['name'], # Assuming 'name' is the unique identifier field
        ^^^^^^^^^^^^^^^^^^^^^^^^^^^^^^^^^^^^^^^^^^^^^^^^^^^^^^^^^^^^^^^^^^^^^^^
    ...<11 lines>...
        }
        ^
    )
    ^
  File "C:\Users\ahmed\AppData\Local\Programs\Python\Python313\Lib\site-packages\django\db\models\manager.py", line 87, in manager_method
    return getattr(self.get_queryset(), name)(*args, **kwargs)
           ~~~~~~~~~~~~~~~~~~~~~~~~~~~~~~~~~~^^^^^^^^^^^^^^^^^
  File "C:\Users\ahmed\AppData\Local\Programs\Python\Python313\Lib\site-packages\django\db\models\query.py", line 918, in get_or_create
    params = self._extract_model_params(defaults, **kwargs)
  File "C:\Users\ahmed\AppData\Local\Programs\Python\Python313\Lib\site-packages\django\db\models\query.py", line 999, in _extract_model_params
    raise exceptions.FieldError(
    ...<5 lines>...
    )
django.core.exceptions.FieldError: Invalid field name(s) for model CommonCategoriesModel: 'end_date', 'start_date'.
ERROR 2025-07-01 21:37:53,333 views 26724 6824 Unexpected error for Category 'Service Category - Consulting'.
Traceback (most recent call last):
  File "C:\Users\ahmed\AppData\Local\Programs\Python\Python313\Lib\site-packages\django\db\models\query.py", line 916, in get_or_create
    return self.get(**kwargs), False
           ~~~~~~~~^^^^^^^^^^
  File "C:\Users\ahmed\AppData\Local\Programs\Python\Python313\Lib\site-packages\django\db\models\query.py", line 637, in get
    raise self.model.DoesNotExist(
        "%s matching query does not exist." % self.model._meta.object_name
    )
allifmaalcommonapp.models.CommonCategoriesModel.DoesNotExist: CommonCategoriesModel matching query does not exist.

During handling of the above exception, another exception occurred:

Traceback (most recent call last):
  File "C:\am\allifapp\allifapperp\allifmaalcommonapp\views.py", line 2190, in commonCreateDefaultValues
    _, created = CommonCategoriesModel.objects.get_or_create(
                 ~~~~~~~~~~~~~~~~~~~~~~~~~~~~~~~~~~~~~~~~~~~^
        name=cat_data['name'], # Assuming 'name' is the unique identifier field
        ^^^^^^^^^^^^^^^^^^^^^^^^^^^^^^^^^^^^^^^^^^^^^^^^^^^^^^^^^^^^^^^^^^^^^^^
    ...<11 lines>...
        }
        ^
    )
    ^
  File "C:\Users\ahmed\AppData\Local\Programs\Python\Python313\Lib\site-packages\django\db\models\manager.py", line 87, in manager_method
    return getattr(self.get_queryset(), name)(*args, **kwargs)
           ~~~~~~~~~~~~~~~~~~~~~~~~~~~~~~~~~~^^^^^^^^^^^^^^^^^
  File "C:\Users\ahmed\AppData\Local\Programs\Python\Python313\Lib\site-packages\django\db\models\query.py", line 918, in get_or_create
    params = self._extract_model_params(defaults, **kwargs)
  File "C:\Users\ahmed\AppData\Local\Programs\Python\Python313\Lib\site-packages\django\db\models\query.py", line 999, in _extract_model_params
    raise exceptions.FieldError(
    ...<5 lines>...
    )
django.core.exceptions.FieldError: Invalid field name(s) for model CommonCategoriesModel: 'end_date', 'start_date'.
ERROR 2025-07-01 21:37:53,444 views 26724 6824 Default setup for Barasho completed with errors. Results: {'company_scopes': {'created': 5, 'skipped': 0, 'errors': []}, 'taxes': {'created': 0, 'skipped': 3, 'errors': ["Error creating tax 'Sales Tax': Cannot resolve keyword 'taxname' into field. Choices are: balance, branch, branch_id, code, comments, company, company_id, date, delete_status, department, department_id, description, division, division_id, ends, id, last_updated, name, number, operation_term, operation_term_id, operation_year, operation_year_id, owner, owner_id, priority, quantity, reference, starts, status, stktxrte, taxrate, taxtype, txinvce, txqr, updated_by, updated_by_id, uuid", "Error creating tax 'VAT': Cannot resolve keyword 'taxname' into field. Choices are: balance, branch, branch_id, code, comments, company, company_id, date, delete_status, department, department_id, description, division, division_id, ends, id, last_updated, name, number, operation_term, operation_term_id, operation_year, operation_year_id, owner, owner_id, priority, quantity, reference, starts, status, stktxrte, taxrate, taxtype, txinvce, txqr, updated_by, updated_by_id, uuid", "Error creating tax 'Withholding Tax': Cannot resolve keyword 'taxname' into field. Choices are: balance, branch, branch_id, code, comments, company, company_id, date, delete_status, department, department_id, description, division, division_id, ends, id, last_updated, name, number, operation_term, operation_term_id, operation_year, operation_year_id, owner, owner_id, priority, quantity, reference, starts, status, stktxrte, taxrate, taxtype, txinvce, txqr, updated_by, updated_by_id, uuid"]}, 'supplier_taxes': {'created': 0, 'skipped': 3, 'errors': ["Error creating supplier tax 'Sales Tax': Cannot resolve keyword 'taxname' into field. Choices are: balance, branch, branch_id, code, comments, company, company_id, date, delete_status, department, department_id, description, division, division_id, ends, id, last_updated, name, number, operation_term, operation_term_id, operation_year, operation_year_id, owner, owner_id, priority, quantity, reference, sppltxrt, starts, status, supplrstktxrte, taxrate, taxtype, updated_by, updated_by_id, uuid", "Error creating supplier tax 'VAT': Cannot resolve keyword 'taxname' into field. Choices are: balance, branch, branch_id, code, comments, company, company_id, date, delete_status, department, department_id, description, division, division_id, ends, id, last_updated, name, number, operation_term, operation_term_id, operation_year, operation_year_id, owner, owner_id, priority, quantity, reference, sppltxrt, starts, status, supplrstktxrte, taxrate, taxtype, updated_by, updated_by_id, uuid", "Error creating supplier tax 'Withholding Tax': Cannot resolve keyword 'taxname' into field. Choices are: balance, branch, branch_id, code, comments, company, company_id, date, delete_status, department, department_id, description, division, division_id, ends, id, last_updated, name, number, operation_term, operation_term_id, operation_year, operation_year_id, owner, owner_id, priority, quantity, reference, sppltxrt, starts, status, supplrstktxrte, taxrate, taxtype, updated_by, updated_by_id, uuid"]}, 'currencies': {'created': 5, 'skipped': 0, 'errors': []}, 'payment_terms': {'created': 6, 'skipped': 0, 'errors': []}, 'units': {'created': 12, 'skipped': 0, 'errors': []}, 'operation_years': {'created': 0, 'skipped': 2, 'errors': ["Error creating year 'Operation Year One': Invalid field name(s) for model CommonOperationYearsModel: 'end_date', 'start_date'.", "Error creating year 'Current Year': Invalid field name(s) for model CommonOperationYearsModel: 'end_date', 'start_date'."]}, 'operation_year_terms': {'created': 0, 'skipped': 8, 'errors': ["Missing parent year 'Operation Year One' for term 'Term One'.", "Missing parent year 'Operation Year One' for term 'Term Two'.", "Missing parent year 'Operation Year One' for term 'Term Three'.", "Missing parent year 'Operation Year One' for term 'Term Four'.", "Missing parent year 'Current Year' for term 'Q1'.", "Missing parent year 'Current Year' for term 'Q2'.", "Missing parent year 'Current Year' for term 'Q3'.", "Missing parent year 'Current Year' for term 'Q4'."]}, 'codes': {'created': 5, 'skipped': 0, 'errors': []}, 'categories': {'created': 0, 'skipped': 4, 'errors': ["Error creating category 'General Category 1': Invalid field name(s) for model CommonCategoriesModel: 'end_date', 'start_date'.", "Error creating category 'General Category 2': Invalid field name(s) for model CommonCategoriesModel: 'end_date', 'start_date'.", "Error creating category 'Product Category - Electronics': Invalid field name(s) for model CommonCategoriesModel: 'end_date', 'start_date'.", "Error creating category 'Service Category - Consulting': Invalid field name(s) for model CommonCategoriesModel: 'end_date', 'start_date'."]}, 'gl_categories': {'created': 5, 'skipped': 0, 'errors': []}, 'chart_of_accounts': {'created': 47, 'skipped': 0, 'errors': []}, 'overall_error': False}
INFO 2025-07-02 07:22:39,889 autoreload 30368 22416 Watching for file changes with StatReloader
INFO 2025-07-02 07:50:17,712 autoreload 30368 22416 C:\am\allifapp\allifapperp\allifmaalshaafiapp\models.py changed, reloading.
INFO 2025-07-02 07:50:19,623 autoreload 2352 23944 Watching for file changes with StatReloader
INFO 2025-07-02 07:50:55,253 autoreload 26888 24208 Watching for file changes with StatReloader
INFO 2025-07-02 07:52:45,820 autoreload 26888 24208 C:\am\allifapp\allifapperp\allifmaalshaafiapp\models.py changed, reloading.
INFO 2025-07-02 07:52:46,940 autoreload 34756 22432 Watching for file changes with StatReloader
INFO 2025-07-02 07:57:40,812 autoreload 34756 22432 C:\am\allifapp\allifapperp\allifmaalshaafiapp\models.py changed, reloading.
INFO 2025-07-02 07:57:42,238 autoreload 26584 3648 Watching for file changes with StatReloader
INFO 2025-07-02 17:26:50,453 autoreload 988 26112 Watching for file changes with StatReloader
INFO 2025-07-02 19:32:21,954 autoreload 988 26112 C:\am\allifapp\allifapperp\allifmaalcommonapp\forms.py changed, reloading.
INFO 2025-07-02 19:32:24,363 autoreload 27100 20736 Watching for file changes with StatReloader
INFO 2025-07-02 20:04:13,637 autoreload 27100 20736 C:\am\allifapp\allifapperp\allifmaalcommonapp\models.py changed, reloading.
INFO 2025-07-02 20:04:15,461 autoreload 792 8244 Watching for file changes with StatReloader
INFO 2025-07-02 20:07:49,118 autoreload 792 8244 C:\am\allifapp\allifapperp\allifmaalcommonapp\views.py changed, reloading.
INFO 2025-07-02 20:07:50,379 autoreload 18264 25724 Watching for file changes with StatReloader
INFO 2025-07-02 20:08:04,572 autoreload 20984 26112 Watching for file changes with StatReloader
INFO 2025-07-02 20:09:12,339 autoreload 20984 26112 C:\am\allifapp\allifapperp\allifmaalcommonapp\views.py changed, reloading.
INFO 2025-07-02 20:09:13,794 autoreload 22624 15436 Watching for file changes with StatReloader
INFO 2025-07-02 20:09:38,931 autoreload 22624 15436 C:\am\allifapp\allifapperp\allifmaalcommonapp\views.py changed, reloading.
INFO 2025-07-02 20:09:39,938 autoreload 28160 9348 Watching for file changes with StatReloader
INFO 2025-07-02 20:09:57,010 autoreload 28160 9348 C:\am\allifapp\allifapperp\allifmaalcommonapp\views.py changed, reloading.
INFO 2025-07-02 20:09:57,917 autoreload 21296 22768 Watching for file changes with StatReloader
INFO 2025-07-02 20:11:15,497 autoreload 21296 22768 C:\am\allifapp\allifapperp\allifmaalcommonapp\preprocessor.py changed, reloading.
INFO 2025-07-02 20:11:16,414 autoreload 10264 32828 Watching for file changes with StatReloader
INFO 2025-07-02 20:12:36,633 autoreload 10264 32828 C:\am\allifapp\allifapperp\allifmaalcommonapp\allifutils.py changed, reloading.
INFO 2025-07-02 20:12:37,527 autoreload 6180 24736 Watching for file changes with StatReloader
ERROR 2025-07-02 20:14:05,827 log 6180 5144 Internal Server Error: /Update/Tax/Parameter/Details/3/user-full-names-ad7b7636d860/barashosadi-road-0f9599a2c896/
Traceback (most recent call last):
  File "C:\am\allifapp\allifapperp\allifmaalcommonapp\views.py", line 4126, in CommonUpdateTaxDetails
    return render(request,'allifmaalcommonapp/taxes/add-update-tax.html',context)
  File "C:\Users\ahmed\AppData\Local\Programs\Python\Python313\Lib\site-packages\django\shortcuts.py", line 24, in render
    content = loader.render_to_string(template_name, context, request, using=using)
  File "C:\Users\ahmed\AppData\Local\Programs\Python\Python313\Lib\site-packages\django\template\loader.py", line 62, in render_to_string
    return template.render(context, request)
           ~~~~~~~~~~~~~~~^^^^^^^^^^^^^^^^^^
  File "C:\Users\ahmed\AppData\Local\Programs\Python\Python313\Lib\site-packages\django\template\backends\django.py", line 61, in render
    return self.template.render(context)
           ~~~~~~~~~~~~~~~~~~~~^^^^^^^^^
  File "C:\Users\ahmed\AppData\Local\Programs\Python\Python313\Lib\site-packages\django\template\base.py", line 173, in render
    with context.bind_template(self):
         ~~~~~~~~~~~~~~~~~~~~~^^^^^^
  File "C:\Users\ahmed\AppData\Local\Programs\Python\Python313\Lib\contextlib.py", line 141, in __enter__
    return next(self.gen)
  File "C:\Users\ahmed\AppData\Local\Programs\Python\Python313\Lib\site-packages\django\template\context.py", line 254, in bind_template
    updates.update(processor(self.request))
                   ~~~~~~~~~^^^^^^^^^^^^^^
  File "C:\am\allifapp\allifapperp\allifmaalcommonapp\preprocessor.py", line 17, in allifmaalcommonappglobalVariables
    print(user_var.user_category,'jjjjjjjjjjjjjjjjj')
          ^^^^^^^^^^^^^^^^^^^^^^
AttributeError: 'str' object has no attribute 'user_category'

During handling of the above exception, another exception occurred:

Traceback (most recent call last):
  File "C:\am\allifapp\allifapperp\allifmaalcommonapp\decorators.py", line 236, in allif_wrapper_func
    return allif_param_func(request,*args,**kwargs)
  File "C:\am\allifapp\allifapperp\allifmaalcommonapp\decorators.py", line 62, in allif_wrapper_func
    return allif_param_func(request,*args,**kwargs)
  File "C:\Users\ahmed\AppData\Local\Programs\Python\Python313\Lib\contextlib.py", line 85, in inner
    return func(*args, **kwds)
  File "C:\am\allifapp\allifapperp\allifmaalcommonapp\views.py", line 4129, in CommonUpdateTaxDetails
    return render(request,'allifmaalcommonapp/error/error.html',error_context)
  File "C:\Users\ahmed\AppData\Local\Programs\Python\Python313\Lib\site-packages\django\shortcuts.py", line 24, in render
    content = loader.render_to_string(template_name, context, request, using=using)
  File "C:\Users\ahmed\AppData\Local\Programs\Python\Python313\Lib\site-packages\django\template\loader.py", line 62, in render_to_string
    return template.render(context, request)
           ~~~~~~~~~~~~~~~^^^^^^^^^^^^^^^^^^
  File "C:\Users\ahmed\AppData\Local\Programs\Python\Python313\Lib\site-packages\django\template\backends\django.py", line 61, in render
    return self.template.render(context)
           ~~~~~~~~~~~~~~~~~~~~^^^^^^^^^
  File "C:\Users\ahmed\AppData\Local\Programs\Python\Python313\Lib\site-packages\django\template\base.py", line 173, in render
    with context.bind_template(self):
         ~~~~~~~~~~~~~~~~~~~~~^^^^^^
  File "C:\Users\ahmed\AppData\Local\Programs\Python\Python313\Lib\contextlib.py", line 141, in __enter__
    return next(self.gen)
  File "C:\Users\ahmed\AppData\Local\Programs\Python\Python313\Lib\site-packages\django\template\context.py", line 254, in bind_template
    updates.update(processor(self.request))
                   ~~~~~~~~~^^^^^^^^^^^^^^
  File "C:\am\allifapp\allifapperp\allifmaalcommonapp\preprocessor.py", line 17, in allifmaalcommonappglobalVariables
    print(user_var.user_category,'jjjjjjjjjjjjjjjjj')
          ^^^^^^^^^^^^^^^^^^^^^^
AttributeError: 'str' object has no attribute 'user_category'

During handling of the above exception, another exception occurred:

Traceback (most recent call last):
  File "C:\Users\ahmed\AppData\Local\Programs\Python\Python313\Lib\site-packages\django\core\handlers\exception.py", line 55, in inner
    response = get_response(request)
  File "C:\Users\ahmed\AppData\Local\Programs\Python\Python313\Lib\site-packages\django\core\handlers\base.py", line 197, in _get_response
    response = wrapped_callback(request, *callback_args, **callback_kwargs)
  File "C:\am\allifapp\allifapperp\allifmaalcommonapp\decorators.py", line 203, in allif_wrapper_func
    return allif_param_func(request,*args,**kwargs)
  File "C:\am\allifapp\allifapperp\allifmaalcommonapp\decorators.py", line 243, in allif_wrapper_func
    return render(request,'allifmaalcommonapp/error/error.html',error_context)
  File "C:\Users\ahmed\AppData\Local\Programs\Python\Python313\Lib\site-packages\django\shortcuts.py", line 24, in render
    content = loader.render_to_string(template_name, context, request, using=using)
  File "C:\Users\ahmed\AppData\Local\Programs\Python\Python313\Lib\site-packages\django\template\loader.py", line 62, in render_to_string
    return template.render(context, request)
           ~~~~~~~~~~~~~~~^^^^^^^^^^^^^^^^^^
  File "C:\Users\ahmed\AppData\Local\Programs\Python\Python313\Lib\site-packages\django\template\backends\django.py", line 61, in render
    return self.template.render(context)
           ~~~~~~~~~~~~~~~~~~~~^^^^^^^^^
  File "C:\Users\ahmed\AppData\Local\Programs\Python\Python313\Lib\site-packages\django\template\base.py", line 173, in render
    with context.bind_template(self):
         ~~~~~~~~~~~~~~~~~~~~~^^^^^^
  File "C:\Users\ahmed\AppData\Local\Programs\Python\Python313\Lib\contextlib.py", line 141, in __enter__
    return next(self.gen)
  File "C:\Users\ahmed\AppData\Local\Programs\Python\Python313\Lib\site-packages\django\template\context.py", line 254, in bind_template
    updates.update(processor(self.request))
                   ~~~~~~~~~^^^^^^^^^^^^^^
  File "C:\am\allifapp\allifapperp\allifmaalcommonapp\preprocessor.py", line 17, in allifmaalcommonappglobalVariables
    print(user_var.user_category,'jjjjjjjjjjjjjjjjj')
          ^^^^^^^^^^^^^^^^^^^^^^
AttributeError: 'str' object has no attribute 'user_category'
WARNING 2025-07-02 20:14:06,044 log 6180 5144 Not Found: /favicon.ico
INFO 2025-07-02 20:14:30,993 autoreload 6180 24736 C:\am\allifapp\allifapperp\allifmaalcommonapp\preprocessor.py changed, reloading.
INFO 2025-07-02 20:14:31,907 autoreload 804 14280 Watching for file changes with StatReloader
INFO 2025-07-02 20:16:03,476 autoreload 804 14280 C:\am\allifapp\allifapperp\allifmaalcommonapp\preprocessor.py changed, reloading.
INFO 2025-07-02 20:16:04,415 autoreload 16896 30728 Watching for file changes with StatReloader
INFO 2025-07-02 20:17:23,444 autoreload 16896 30728 C:\am\allifapp\allifapperp\allifmaalcommonapp\views.py changed, reloading.
INFO 2025-07-02 20:17:24,551 autoreload 12176 11724 Watching for file changes with StatReloader
ERROR 2025-07-02 20:21:32,021 log 12176 22976 Internal Server Error: /Allifmaal/Application/For/Users/And/Accounts/Management/User/Login/Page/
Traceback (most recent call last):
  File "C:\am\allifapp\allifapperp\allifmaalusersapp\views.py", line 55, in userLoginPage
    return render(request,"allifmaalusersapp/users/user_login.html",context)
  File "C:\Users\ahmed\AppData\Local\Programs\Python\Python313\Lib\site-packages\django\shortcuts.py", line 24, in render
    content = loader.render_to_string(template_name, context, request, using=using)
  File "C:\Users\ahmed\AppData\Local\Programs\Python\Python313\Lib\site-packages\django\template\loader.py", line 62, in render_to_string
    return template.render(context, request)
           ~~~~~~~~~~~~~~~^^^^^^^^^^^^^^^^^^
  File "C:\Users\ahmed\AppData\Local\Programs\Python\Python313\Lib\site-packages\django\template\backends\django.py", line 61, in render
    return self.template.render(context)
           ~~~~~~~~~~~~~~~~~~~~^^^^^^^^^
  File "C:\Users\ahmed\AppData\Local\Programs\Python\Python313\Lib\site-packages\django\template\base.py", line 173, in render
    with context.bind_template(self):
         ~~~~~~~~~~~~~~~~~~~~~^^^^^^
  File "C:\Users\ahmed\AppData\Local\Programs\Python\Python313\Lib\contextlib.py", line 141, in __enter__
    return next(self.gen)
  File "C:\Users\ahmed\AppData\Local\Programs\Python\Python313\Lib\site-packages\django\template\context.py", line 254, in bind_template
    updates.update(processor(self.request))
                   ~~~~~~~~~^^^^^^^^^^^^^^
  File "C:\am\allifapp\allifapperp\allifmaalcommonapp\preprocessor.py", line 46, in allifmaalcommonappglobalVariables
    "allifapp_logged_user_category":allifapp_logged_user_category,
                                    ^^^^^^^^^^^^^^^^^^^^^^^^^^^^^
UnboundLocalError: cannot access local variable 'allifapp_logged_user_category' where it is not associated with a value

During handling of the above exception, another exception occurred:

Traceback (most recent call last):
  File "C:\Users\ahmed\AppData\Local\Programs\Python\Python313\Lib\site-packages\django\core\handlers\exception.py", line 55, in inner
    response = get_response(request)
  File "C:\Users\ahmed\AppData\Local\Programs\Python\Python313\Lib\site-packages\django\core\handlers\base.py", line 197, in _get_response
    response = wrapped_callback(request, *callback_args, **callback_kwargs)
  File "C:\am\allifapp\allifapperp\allifmaalusersapp\views.py", line 58, in userLoginPage
    return render(request,'allifmaalusersapp/error/error.html',error_context)
  File "C:\Users\ahmed\AppData\Local\Programs\Python\Python313\Lib\site-packages\django\shortcuts.py", line 24, in render
    content = loader.render_to_string(template_name, context, request, using=using)
  File "C:\Users\ahmed\AppData\Local\Programs\Python\Python313\Lib\site-packages\django\template\loader.py", line 62, in render_to_string
    return template.render(context, request)
           ~~~~~~~~~~~~~~~^^^^^^^^^^^^^^^^^^
  File "C:\Users\ahmed\AppData\Local\Programs\Python\Python313\Lib\site-packages\django\template\backends\django.py", line 61, in render
    return self.template.render(context)
           ~~~~~~~~~~~~~~~~~~~~^^^^^^^^^
  File "C:\Users\ahmed\AppData\Local\Programs\Python\Python313\Lib\site-packages\django\template\base.py", line 173, in render
    with context.bind_template(self):
         ~~~~~~~~~~~~~~~~~~~~~^^^^^^
  File "C:\Users\ahmed\AppData\Local\Programs\Python\Python313\Lib\contextlib.py", line 141, in __enter__
    return next(self.gen)
  File "C:\Users\ahmed\AppData\Local\Programs\Python\Python313\Lib\site-packages\django\template\context.py", line 254, in bind_template
    updates.update(processor(self.request))
                   ~~~~~~~~~^^^^^^^^^^^^^^
  File "C:\am\allifapp\allifapperp\allifmaalcommonapp\preprocessor.py", line 46, in allifmaalcommonappglobalVariables
    "allifapp_logged_user_category":allifapp_logged_user_category,
                                    ^^^^^^^^^^^^^^^^^^^^^^^^^^^^^
UnboundLocalError: cannot access local variable 'allifapp_logged_user_category' where it is not associated with a value
ERROR 2025-07-02 20:21:37,532 log 12176 22976 Internal Server Error: /Allifmaal/Application/For/Users/And/Accounts/Management/User/Login/Page/
Traceback (most recent call last):
  File "C:\am\allifapp\allifapperp\allifmaalusersapp\views.py", line 55, in userLoginPage
    return render(request,"allifmaalusersapp/users/user_login.html",context)
  File "C:\Users\ahmed\AppData\Local\Programs\Python\Python313\Lib\site-packages\django\shortcuts.py", line 24, in render
    content = loader.render_to_string(template_name, context, request, using=using)
  File "C:\Users\ahmed\AppData\Local\Programs\Python\Python313\Lib\site-packages\django\template\loader.py", line 62, in render_to_string
    return template.render(context, request)
           ~~~~~~~~~~~~~~~^^^^^^^^^^^^^^^^^^
  File "C:\Users\ahmed\AppData\Local\Programs\Python\Python313\Lib\site-packages\django\template\backends\django.py", line 61, in render
    return self.template.render(context)
           ~~~~~~~~~~~~~~~~~~~~^^^^^^^^^
  File "C:\Users\ahmed\AppData\Local\Programs\Python\Python313\Lib\site-packages\django\template\base.py", line 173, in render
    with context.bind_template(self):
         ~~~~~~~~~~~~~~~~~~~~~^^^^^^
  File "C:\Users\ahmed\AppData\Local\Programs\Python\Python313\Lib\contextlib.py", line 141, in __enter__
    return next(self.gen)
  File "C:\Users\ahmed\AppData\Local\Programs\Python\Python313\Lib\site-packages\django\template\context.py", line 254, in bind_template
    updates.update(processor(self.request))
                   ~~~~~~~~~^^^^^^^^^^^^^^
  File "C:\am\allifapp\allifapperp\allifmaalcommonapp\preprocessor.py", line 46, in allifmaalcommonappglobalVariables
    "allifapp_logged_user_category":allifapp_logged_user_category,
                                    ^^^^^^^^^^^^^^^^^^^^^^^^^^^^^
UnboundLocalError: cannot access local variable 'allifapp_logged_user_category' where it is not associated with a value

During handling of the above exception, another exception occurred:

Traceback (most recent call last):
  File "C:\Users\ahmed\AppData\Local\Programs\Python\Python313\Lib\site-packages\django\core\handlers\exception.py", line 55, in inner
    response = get_response(request)
  File "C:\Users\ahmed\AppData\Local\Programs\Python\Python313\Lib\site-packages\django\core\handlers\base.py", line 197, in _get_response
    response = wrapped_callback(request, *callback_args, **callback_kwargs)
  File "C:\am\allifapp\allifapperp\allifmaalusersapp\views.py", line 58, in userLoginPage
    return render(request,'allifmaalusersapp/error/error.html',error_context)
  File "C:\Users\ahmed\AppData\Local\Programs\Python\Python313\Lib\site-packages\django\shortcuts.py", line 24, in render
    content = loader.render_to_string(template_name, context, request, using=using)
  File "C:\Users\ahmed\AppData\Local\Programs\Python\Python313\Lib\site-packages\django\template\loader.py", line 62, in render_to_string
    return template.render(context, request)
           ~~~~~~~~~~~~~~~^^^^^^^^^^^^^^^^^^
  File "C:\Users\ahmed\AppData\Local\Programs\Python\Python313\Lib\site-packages\django\template\backends\django.py", line 61, in render
    return self.template.render(context)
           ~~~~~~~~~~~~~~~~~~~~^^^^^^^^^
  File "C:\Users\ahmed\AppData\Local\Programs\Python\Python313\Lib\site-packages\django\template\base.py", line 173, in render
    with context.bind_template(self):
         ~~~~~~~~~~~~~~~~~~~~~^^^^^^
  File "C:\Users\ahmed\AppData\Local\Programs\Python\Python313\Lib\contextlib.py", line 141, in __enter__
    return next(self.gen)
  File "C:\Users\ahmed\AppData\Local\Programs\Python\Python313\Lib\site-packages\django\template\context.py", line 254, in bind_template
    updates.update(processor(self.request))
                   ~~~~~~~~~^^^^^^^^^^^^^^
  File "C:\am\allifapp\allifapperp\allifmaalcommonapp\preprocessor.py", line 46, in allifmaalcommonappglobalVariables
    "allifapp_logged_user_category":allifapp_logged_user_category,
                                    ^^^^^^^^^^^^^^^^^^^^^^^^^^^^^
UnboundLocalError: cannot access local variable 'allifapp_logged_user_category' where it is not associated with a value
INFO 2025-07-02 20:22:04,029 autoreload 12176 11724 C:\am\allifapp\allifapperp\allifmaalcommonapp\preprocessor.py changed, reloading.
INFO 2025-07-02 20:22:04,767 autoreload 27592 29804 Watching for file changes with StatReloader
INFO 2025-07-02 20:30:44,631 autoreload 27592 29804 C:\am\allifapp\allifapperp\allifmaalcommonapp\models.py changed, reloading.
INFO 2025-07-02 20:30:45,867 autoreload 31928 23400 Watching for file changes with StatReloader
INFO 2025-07-02 20:31:23,674 autoreload 21564 26712 Watching for file changes with StatReloader
INFO 2025-07-02 20:33:42,872 autoreload 21564 26712 C:\am\allifapp\allifapperp\allifmaalusersapp\admin.py changed, reloading.
INFO 2025-07-02 20:33:43,992 autoreload 12164 11596 Watching for file changes with StatReloader
INFO 2025-07-02 20:48:35,044 autoreload 12164 11596 C:\am\allifapp\allifapperp\allifmaalcommonapp\models.py changed, reloading.
INFO 2025-07-02 20:48:36,061 autoreload 19768 29216 Watching for file changes with StatReloader
INFO 2025-07-02 20:50:31,659 autoreload 19768 29216 C:\am\allifapp\allifapperp\allifmaalcommonapp\forms.py changed, reloading.
INFO 2025-07-02 20:50:32,544 autoreload 6200 31336 Watching for file changes with StatReloader
INFO 2025-07-02 20:53:55,649 autoreload 10868 27540 Watching for file changes with StatReloader
INFO 2025-07-02 20:56:39,221 autoreload 10868 27540 C:\am\allifapp\allifapperp\allifmaalcommonapp\forms.py changed, reloading.
INFO 2025-07-02 20:56:40,218 autoreload 2952 36740 Watching for file changes with StatReloader
INFO 2025-07-02 20:59:54,113 autoreload 2952 36740 C:\am\allifapp\allifapperp\allifmaalcommonapp\forms.py changed, reloading.
INFO 2025-07-02 20:59:55,184 autoreload 35252 21708 Watching for file changes with StatReloader
INFO 2025-07-02 21:07:30,761 autoreload 35252 21708 C:\am\allifapp\allifapperp\allifmaalcommonapp\forms.py changed, reloading.
INFO 2025-07-02 21:07:31,883 autoreload 31476 10516 Watching for file changes with StatReloader
INFO 2025-07-02 22:05:05,845 autoreload 31476 10516 C:\am\allifapp\allifapperp\allifapperp\settings.py changed, reloading.
INFO 2025-07-02 22:05:06,937 autoreload 9512 31256 Watching for file changes with StatReloader
INFO 2025-07-02 22:05:09,770 autoreload 9512 31256 C:\am\allifapp\allifapperp\allifapperp\settings.py changed, reloading.
INFO 2025-07-02 22:05:10,561 autoreload 25944 35284 Watching for file changes with StatReloader
WARNING 2025-07-02 22:09:44,242 erp_ui_tags 25944 2072 render_display_field_row: Field 'name' not found on instance .
WARNING 2025-07-02 22:09:44,244 erp_ui_tags 25944 2072 render_display_field_row: Field 'description' not found on instance .
WARNING 2025-07-02 22:09:44,244 erp_ui_tags 25944 2072 render_display_field_row: Field 'taxrate' not found on instance .
WARNING 2025-07-02 22:09:44,244 erp_ui_tags 25944 2072 render_display_field_row: Field 'taxtype' not found on instance .
WARNING 2025-07-02 22:09:44,245 erp_ui_tags 25944 2072 render_display_field_row: Field 'tax_assumptions' not found on instance .
WARNING 2025-07-02 22:09:44,245 erp_ui_tags 25944 2072 render_display_field_row: Field 'tax_resources' not found on instance .
WARNING 2025-07-02 22:09:44,245 erp_ui_tags 25944 2072 render_display_field_row: Field 'tax_risks' not found on instance .
WARNING 2025-07-02 22:09:44,245 erp_ui_tags 25944 2072 render_display_field_row: Field 'tax_stakeholders' not found on instance .
INFO 2025-07-02 22:12:22,777 autoreload 25944 35284 C:\am\allifapp\allifapperp\allifmaalcommonapp\views.py changed, reloading.
INFO 2025-07-02 22:12:24,002 autoreload 25888 16104 Watching for file changes with StatReloader
INFO 2025-07-02 22:13:08,876 autoreload 20572 5096 Watching for file changes with StatReloader
INFO 2025-07-02 22:29:03,875 autoreload 20572 5096 C:\am\allifapp\allifapperp\allifmaalcommonapp\templatetags\erp_ui_tags.py changed, reloading.
INFO 2025-07-02 22:29:04,813 autoreload 13804 24776 Watching for file changes with StatReloader
INFO 2025-07-02 22:32:17,937 autoreload 13804 24776 C:\am\allifapp\allifapperp\allifmaalcommonapp\templatetags\erp_ui_tags.py changed, reloading.
INFO 2025-07-02 22:32:18,962 autoreload 30512 12300 Watching for file changes with StatReloader
INFO 2025-07-03 18:15:44,891 autoreload 1012 10300 Watching for file changes with StatReloader
INFO 2025-07-03 18:39:09,614 autoreload 1012 10300 C:\am\allifapp\allifapperp\allifapperp\settings.py changed, reloading.
INFO 2025-07-03 18:39:10,874 autoreload 36696 5416 Watching for file changes with StatReloader
ERROR 2025-07-03 18:56:18,685 views 36696 35080 An unexpected error occurred in commonTaxParameters view for user barasho@barasho.com: 'erp_ui_tags' is not a registered tag library. Must be one of:
admin_list
admin_modify
admin_urls
allif_contextual_action_tags
allif_navigation_tags
cache
crispy_forms_field
crispy_forms_filters
crispy_forms_tags
crispy_forms_utils
humanize
i18n
import_export_tags
l10n
log
static
tz
Traceback (most recent call last):
  File "C:\Users\ahmed\AppData\Local\Programs\Python\Python313\Lib\site-packages\django\template\defaulttags.py", line 1026, in find_library
    return parser.libraries[name]
           ~~~~~~~~~~~~~~~~^^^^^^
KeyError: 'erp_ui_tags'

During handling of the above exception, another exception occurred:

Traceback (most recent call last):
  File "C:\am\allifapp\allifapperp\allifmaalcommonapp\views.py", line 4042, in commonTaxParameters
    return render(request, 'allifmaalcommonapp/taxes/taxes.html', context)
  File "C:\Users\ahmed\AppData\Local\Programs\Python\Python313\Lib\site-packages\django\shortcuts.py", line 24, in render
    content = loader.render_to_string(template_name, context, request, using=using)
  File "C:\Users\ahmed\AppData\Local\Programs\Python\Python313\Lib\site-packages\django\template\loader.py", line 61, in render_to_string
    template = get_template(template_name, using=using)
  File "C:\Users\ahmed\AppData\Local\Programs\Python\Python313\Lib\site-packages\django\template\loader.py", line 15, in get_template
    return engine.get_template(template_name)
           ~~~~~~~~~~~~~~~~~~~^^^^^^^^^^^^^^^
  File "C:\Users\ahmed\AppData\Local\Programs\Python\Python313\Lib\site-packages\django\template\backends\django.py", line 33, in get_template
    return Template(self.engine.get_template(template_name), self)
                    ~~~~~~~~~~~~~~~~~~~~~~~~^^^^^^^^^^^^^^^
  File "C:\Users\ahmed\AppData\Local\Programs\Python\Python313\Lib\site-packages\django\template\engine.py", line 175, in get_template
    template, origin = self.find_template(template_name)
                       ~~~~~~~~~~~~~~~~~~^^^^^^^^^^^^^^^
  File "C:\Users\ahmed\AppData\Local\Programs\Python\Python313\Lib\site-packages\django\template\engine.py", line 157, in find_template
    template = loader.get_template(name, skip=skip)
  File "C:\Users\ahmed\AppData\Local\Programs\Python\Python313\Lib\site-packages\django\template\loaders\cached.py", line 57, in get_template
    template = super().get_template(template_name, skip)
  File "C:\Users\ahmed\AppData\Local\Programs\Python\Python313\Lib\site-packages\django\template\loaders\base.py", line 28, in get_template
    return Template(
        contents,
    ...<2 lines>...
        self.engine,
    )
  File "C:\Users\ahmed\AppData\Local\Programs\Python\Python313\Lib\site-packages\django\template\base.py", line 154, in __init__
    self.nodelist = self.compile_nodelist()
                    ~~~~~~~~~~~~~~~~~~~~~^^
  File "C:\Users\ahmed\AppData\Local\Programs\Python\Python313\Lib\site-packages\django\template\base.py", line 200, in compile_nodelist
    return parser.parse()
           ~~~~~~~~~~~~^^
  File "C:\Users\ahmed\AppData\Local\Programs\Python\Python313\Lib\site-packages\django\template\base.py", line 513, in parse
    raise self.error(token, e)
  File "C:\Users\ahmed\AppData\Local\Programs\Python\Python313\Lib\site-packages\django\template\base.py", line 511, in parse
    compiled_result = compile_func(self, token)
  File "C:\Users\ahmed\AppData\Local\Programs\Python\Python313\Lib\site-packages\django\template\loader_tags.py", line 293, in do_extends
    nodelist = parser.parse()
  File "C:\Users\ahmed\AppData\Local\Programs\Python\Python313\Lib\site-packages\django\template\base.py", line 513, in parse
    raise self.error(token, e)
  File "C:\Users\ahmed\AppData\Local\Programs\Python\Python313\Lib\site-packages\django\template\base.py", line 511, in parse
    compiled_result = compile_func(self, token)
  File "C:\Users\ahmed\AppData\Local\Programs\Python\Python313\Lib\site-packages\django\template\defaulttags.py", line 1088, in load
    lib = find_library(parser, name)
  File "C:\Users\ahmed\AppData\Local\Programs\Python\Python313\Lib\site-packages\django\template\defaulttags.py", line 1028, in find_library
    raise TemplateSyntaxError(
    ...<5 lines>...
    )
django.template.exceptions.TemplateSyntaxError: 'erp_ui_tags' is not a registered tag library. Must be one of:
admin_list
admin_modify
admin_urls
allif_contextual_action_tags
allif_navigation_tags
cache
crispy_forms_field
crispy_forms_filters
crispy_forms_tags
crispy_forms_utils
humanize
i18n
import_export_tags
l10n
log
static
tz
INFO 2025-07-03 19:34:00,622 autoreload 36696 5416 C:\am\allifapp\allifapperp\allifmaalcommonapp\models.py changed, reloading.
INFO 2025-07-03 19:34:03,204 autoreload 10868 30504 Watching for file changes with StatReloader
WARNING 2025-07-03 21:06:39,250 log 10868 5128 Not Found: /favicon.ico
